<?xml version="1.0" ?>
<sdf version="1.6">
  <model name='Dolly'>
    <pose>0 0 0.225 0 -0 0</pose>
    <link name='chassis'>
      <inertial>
        <mass>1.0</mass>
        <inertia>
          <ixx>0.0227</ixx>
          <ixy>0</ixy>
          <ixz>0</ixz>
          <iyy>0.0852</iyy>
          <iyz>0</iyz>
          <izz>0.1041</izz>
        </inertia>
      </inertial>
      <visual name='visual'>
        <geometry>
          <box>
            <size>1.0 0.5 0.15</size>
          </box>
        </geometry>
        <material>
          <script>
            <uri>model://dolly/materials/scripts</uri>
            <uri>model://dolly/materials/textures</uri>
            <name>Dolly/fur</name>
          </script>
        </material>
      </visual>
      <!-- <visual name="visual">
     <pose frame="">0 0 0.015 0 0 0</pose>
      <geometry>
      <mesh>
      <uri>model://realsense_camera/meshes/realsense.dae</uri>
      </mesh>
      </geometry>
      </visual> -->
      <!-- <visual name="box">
        <pose>0.1 0 0 0 0 0</pose>
        <geometry>
          <mesh>
            <uri>model://realsense_vamera/meshes/realsense.dae</uri>
            <scale>1.25931896 1.007455168 0.755591376</scale>
          </mesh>
        </geometry>
      </visual> -->
      <sensor name="sensor_ray" type="gpu_ray">
        <pose>0.5 0 0 0 0 0</pose>
        <ray>
          <scan>
            <horizontal>
              <samples>200</samples>
              <resolution>0.5</resolution>
             <min_angle>-0.5</min_angle>
             <max_angle>0.5</max_angle>
            </horizontal>
            <vertical>
              <samples>200</samples>
              <resolution>0.5</resolution>
             <min_angle>-0.5</min_angle>
             <max_angle>0.5</max_angle>
            </vertical>
          </scan>
          <range>
            <min>0.05</min>
        <max>5</max>
        <resolution>0.02</resolution>
          </range>
        </ray>
        <always_on>true</always_on>
        <visualize>true</visualize>
        <update_rate>100.0</update_rate>
        <plugin name="laser" filename="libgazebo_ros_ray_sensor.so">
          <ros>
            <namespace>/dolly</namespace>
            <remapping>~/out:=pointcloud</remapping>
          </ros>
          <output_type>sensor_msgs/PointCloud2</output_type>
        </plugin>
      </sensor>
    </link>

    <link name='caster'>
      <pose>-0.3 0 -0.125 0 0 0</pose>
      <inertial>
        <mass>0.0415553</mass>
        <inertia>
          <ixx>7.97741e-05</ixx>
          <ixy>0</ixy>
          <ixz>0</ixz>
          <iyy>7.97741e-05</iyy>
          <iyz>0</iyz>
          <izz>7.97741e-05</izz>
        </inertia>
      </inertial>
      <visual name='visual'>
        <geometry>
          <sphere>
            <radius>0.1</radius>
          </sphere>
        </geometry>
        <material>
          <diffuse>0.5 0.5 0.5 1</diffuse>
          <ambient>0 0 0 1</ambient>
          <specular>1 1 1 1</specular>
          <emissive>0 0 0 1</emissive>
        </material>
      </visual>
      <collision name='collision'>
        <geometry>
          <sphere>
            <radius>0.1</radius>
          </sphere>
        </geometry>
        <surface>
          <friction>
            <ode>
              <mu>1</mu>
              <mu2>1</mu2>
              <slip1>0</slip1>
              <slip2>0</slip2>
            </ode>
          </friction>
          <contact>
            <ode>
              <soft_cfm>0</soft_cfm>
              <soft_erp>0.2</soft_erp>
              <kp>1e+13</kp>
              <kd>1</kd>
              <max_vel>0.01</max_vel>
              <min_depth>0</min_depth>
            </ode>
          </contact>
        </surface>
      </collision>
    </link>

    <link name='left_wheel'>
      <pose>0.3 0.3 -0.075 -1.5707 0 0</pose>
      <inertial>
        <mass>0.5</mass>
        <inertia>
          <ixx>0.0029</ixx>
          <ixy>0</ixy>
          <ixz>0</ixz>
          <iyy>0.0029</iyy>
          <iyz>0</iyz>
          <izz>0.0056</izz>
        </inertia>
      </inertial>
      <visual name='visual'>
        <geometry>
          <cylinder>
            <radius>0.15</radius>
            <length>0.05</length>
          </cylinder>
        </geometry>
        <material>
          <diffuse>0.5 0.5 0.5 1</diffuse>
          <ambient>0 0 0 1</ambient>
          <specular>1 1 1 1</specular>
          <emissive>0 0 0 1</emissive>
        </material>
      </visual>
      <collision name='collision'>
        <geometry>
          <sphere>
            <radius>0.15</radius>
          </sphere>
        </geometry>
        <surface>
          <friction>
            <ode>
              <mu>1</mu>
              <mu2>1</mu2>
              <slip1>0</slip1>
              <slip2>0</slip2>
            </ode>
          </friction>
          <contact>
            <ode>
              <soft_cfm>0</soft_cfm>
              <soft_erp>0.2</soft_erp>
              <kp>1e+13</kp>
              <kd>1</kd>
              <max_vel>0.01</max_vel>
              <min_depth>0.01</min_depth>
            </ode>
          </contact>
        </surface>
      </collision>
    </link>

    <link name='right_wheel'>
      <pose>0.3 -0.3 -0.075 -1.5707 0 0</pose>
      <inertial>
        <mass>0.5</mass>
        <inertia>
          <ixx>0.0029</ixx>
          <ixy>0</ixy>
          <ixz>0</ixz>
          <iyy>0.0029</iyy>
          <iyz>0</iyz>
          <izz>0.0056</izz>
        </inertia>
      </inertial>
      <visual name='visual'>
        <geometry>
          <cylinder>
            <radius>0.15</radius>
            <length>0.05</length>
          </cylinder>
        </geometry>
        <material>
          <diffuse>0.5 0.5 0.5 1</diffuse>
          <ambient>0 0 0 1</ambient>
          <specular>1 1 1 1</specular>
          <emissive>0 0 0 1</emissive>
        </material>
      </visual>
      <collision name='collision'>
        <geometry>
          <sphere>
            <radius>0.15</radius>
          </sphere>
        </geometry>
        <surface>
          <friction>
            <ode>
              <mu>1</mu>
              <mu2>1</mu2>
              <slip1>0</slip1>
              <slip2>0</slip2>
            </ode>
          </friction>
          <contact>
            <ode>
              <soft_cfm>0</soft_cfm>
              <soft_erp>0.2</soft_erp>
              <kp>1e+13</kp>
              <kd>1</kd>
              <max_vel>0.01</max_vel>
              <min_depth>0.01</min_depth>
            </ode>
          </contact>
        </surface>
      </collision>
    </link>

    <!-- <link name='tail'>
      <pose>-0.52 0 0 -1.6 0 0</pose>
      <inertial>
        <mass>0.0254232</mass>
        <inertia>
          <ixx>1.528e-05</ixx>
          <ixy>0</ixy>
          <ixz>0</ixz>
          <iyy>1.528e-05</iyy>
          <iyz>0</iyz>
          <izz>3.45e-06</izz>
        </inertia>
        <pose frame=''>0 0 -0.04 0 -0 0</pose>
      </inertial>
      <visual name='visual'>
        <geometry>
          <cylinder>
            <radius>0.016468</radius>
            <length>0.08</length>
          </cylinder>
        </geometry>
        <material>
          <script>
            <uri>model://dolly/materials/scripts</uri>
            <uri>model://dolly/materials/textures</uri>
            <name>Dolly/fur</name>
          </script>
        </material>
      </visual>
    </link> -->
    <link name="cam">
      <inertial>
        <mass>0.0615752</mass>
        <inertia>
          <ixx>9.108e-05</ixx>
          <ixy>0</ixy>
          <ixz>0</ixz>
          <iyy>2.51e-06</iyy>
          <iyz>0</iyz>
          <izz>8.931e-05</izz>
        </inertia>
        <pose frame=''>0 0 0 0 -0 0</pose>
      </inertial>
      <self_collide>0</self_collide>
      <enable_wind>0</enable_wind>
      <kinematic>0</kinematic>
      <gravity>1</gravity>
      <collision name='collision'>
        <laser_retro>0</laser_retro>
        <max_contacts>10</max_contacts>
        <pose frame=''>0 0 0 0 -0 0</pose>
        <geometry>
          <box>
            <size>0.0078 0.130 0.0192</size>
          </box>
        </geometry>
        <surface>
          <friction>
            <ode>
              <mu>1</mu>
              <mu2>1</mu2>
              <fdir1>0 0 0</fdir1>
              <slip1>0</slip1>
              <slip2>0</slip2>
            </ode>
            <torsional>
              <coefficient>1</coefficient>
              <patch_radius>0</patch_radius>
              <surface_radius>0</surface_radius>
              <use_patch_radius>1</use_patch_radius>
              <ode>
                <slip>0</slip>
              </ode>
            </torsional>
          </friction>
          <bounce>
            <restitution_coefficient>0</restitution_coefficient>
            <threshold>1e+06</threshold>
          </bounce>
          <contact>
            <collide_without_contact>0</collide_without_contact>
            <collide_without_contact_bitmask>1</collide_without_contact_bitmask>
            <collide_bitmask>1</collide_bitmask>
            <ode>
              <soft_cfm>0</soft_cfm>
              <soft_erp>0.2</soft_erp>
              <kp>1e+13</kp>
              <kd>1</kd>
              <max_vel>0.01</max_vel>
              <min_depth>0</min_depth>
            </ode>
            <bullet>
              <split_impulse>1</split_impulse>
              <split_impulse_penetration_threshold>-0.01</split_impulse_penetration_threshold>
              <soft_cfm>0</soft_cfm>
              <soft_erp>0.2</soft_erp>
              <kp>1e+13</kp>
              <kd>1</kd>
            </bullet>
          </contact>
        </surface>
      </collision>
      <sensor name="color" type="camera">
        <pose frame="">0 -0.046 0.004 0 0 0</pose>
        <camera name="__default__">
          <horizontal_fov>1.047</horizontal_fov>
          <image>
            <width>640</width>
            <height>480</height>
            <format>RGB_INT8</format>
          </image>
          <clip>
            <near>0.1</near>
            <far>100</far>
          </clip>
          <noise>
            <type>gaussian</type>
            <mean>0.0</mean>
            <stddev>0.007</stddev>
          </noise>
        </camera>
        <always_on>1</always_on>
        <update_rate>60</update_rate>
        <visualize>1</visualize>
      </sensor>
      <sensor name="ired1" type="camera">
        <pose frame="">0 -0.06 0.004 0 0 0</pose>
        <camera name="__default__">
          <horizontal_fov>1.047</horizontal_fov>
          <image>
            <width>640</width>
            <height>480</height>
            <format>L_INT8</format>
          </image>
          <clip>
            <near>0.1</near>
            <far>100</far>
          </clip>
          <noise>
            <type>gaussian</type>
            <mean>0.0</mean>
            <stddev>0.007</stddev>
          </noise>
        </camera>
        <always_on>1</always_on>
        <update_rate>60</update_rate>
        <visualize>0</visualize>
      </sensor>
      <sensor name="ired2" type="camera">
        <pose frame="">0 0.01 0.004 0 0 0</pose>
        <camera name="__default__">
          <horizontal_fov>1.047</horizontal_fov>
          <image>
            <width>640</width>
            <height>480</height>
            <format>L_INT8</format>
          </image>
          <clip>
            <near>0.1</near>
            <far>100</far>
          </clip>
          <noise>
            <type>gaussian</type>
            <mean>0.0</mean>
            <stddev>0.007</stddev>
          </noise>
        </camera>
        <always_on>1</always_on>
        <update_rate>60</update_rate>
        <visualize>0</visualize>
      </sensor>
      <sensor name="depth" type="depth">
        <pose frame="">0 -0.03 0.004 0 0 0</pose>
        <camera name="__default__">
          <horizontal_fov>1.047</horizontal_fov>
          <image>
            <width>640</width>
            <height>480</height>
          </image>
          <clip>
            <near>0.1</near>
            <far>100</far>
          </clip>
          <noise>
            <type>gaussian</type>
            <mean>0.0</mean>
            <stddev>0.007</stddev>
          </noise>
        </camera>
        <plugin name="intel_realsense_d430_depth_driver" filename="libgazebo_ros_camera.so">
           <ros>
              <namespace>custom_ns</namespace>
              <argument>image_raw:=custom_img</argument>
              <argument>camera_info:=custom_info</argument>
              <argument>depth/image_raw:=depth/image_rect_raw</argument>
              <!-- <argument>camera_info:=camera_info</argument>
              <argument>depth/camera_info:=depth/camera_info</argument>
              <argument>points:=depth/points</argument> -->
            </ros>
            <camera_name>tai</camera_name>
            <frame_name>tai_link_optical</frame_name>
            <hack_baseline>0.07</hack_baseline>
            <min_depth>0.05</min_depth>
            <max_depth>8.0</max_depth>
        </plugin>
        <always_on>1</always_on>
        <update_rate>60</update_rate>
        <visualize>0</visualize>
      </sensor>
    </link>
     

    <joint name='left_wheel_joint' type='revolute'>
      <parent>chassis</parent>
      <child>left_wheel</child>
      <axis>
        <xyz>0 0 1</xyz>
        <limit>
          <lower>-1.79769e+308</lower>
          <upper>1.79769e+308</upper>
        </limit>
      </axis>
    </joint>

    <joint name='right_wheel_joint' type='revolute'>
      <parent>chassis</parent>
      <child>right_wheel</child>
      <axis>
        <xyz>0 0 1</xyz>
        <limit>
          <lower>-1.79769e+308</lower>
          <upper>1.79769e+308</upper>
        </limit>
      </axis>
    </joint>

    <joint name='caster_wheel' type='ball'>
      <parent>chassis</parent>
      <child>caster</child>
    </joint>
        <joint name='cam_link' type='ball'>
      <parent>chassis</parent>
      <child>cam</child>
    </joint>
<!-- 
    <joint name='tail_joint' type='revolute'>
      <parent>chassis</parent>
      <child>tail</child>
      <pose>0 0 0.04 0 -0 0</pose>
      <axis>
        <xyz>1 0 0</xyz>
        <use_parent_model_frame>0</use_parent_model_frame>
        <limit>
          <lower>-1.79769e+308</lower>
          <upper>1.79769e+308</upper>
          <effort>-1</effort>
          <velocity>-1</velocity>
        </limit>
        <dynamics>
          <spring_reference>0</spring_reference>
          <spring_stiffness>0</spring_stiffness>
          <damping>0</damping>
          <friction>0</friction>
        </dynamics>
      </axis>
      <physics>
        <ode>
          <limit>
            <cfm>0</cfm>
            <erp>0.2</erp>
          </limit>
          <suspension>
            <cfm>0</cfm>
            <erp>0.2</erp>
          </suspension>
        </ode>
      </physics>
    </joint> -->

    <plugin name='diff_drive' filename='libgazebo_ros_diff_drive.so'>

      <ros>
        <namespace>/dolly</namespace>
      </ros>

      <!-- wheels -->
      <left_joint>left_wheel_joint</left_joint>
      <right_joint>right_wheel_joint</right_joint>

      <!-- kinematics -->
      <wheel_separation>1.25</wheel_separation>
      <wheel_diameter>0.3</wheel_diameter>

      <!-- limits -->
      <max_wheel_torque>20</max_wheel_torque>
      <max_wheel_acceleration>1.0</max_wheel_acceleration>

      <!-- output -->
      <publish_odom>true</publish_odom>
      <publish_odom_tf>true</publish_odom_tf>

      <odometry_frame>odom_demo</odometry_frame>
      <robot_base_frame>chassis</robot_base_frame>

    </plugin>
  
    <plugin name="realsense_plugin" filename="libRealSensePlugin.so"/>
  
 
  

  </model>
</sdf>
